Workbook

Sheet Cockpit
B2: Projekt-Cockpit: Interviewplanung
B4: Status Übersicht | E4: Team Auslastung | H4: Top Städte | K4: Top Angebotstypen
B5: Status | C5: Anzahl | E5: Name | F5: Einsätze | H5: Stadt | I5: Anzahl | K5: Typ | L5: Anzahl
B6: Kontaktiert | C6: =COUNTIF('Übersicht'!F$5:F$500, "Kontaktiert") -> 41 | E6: Andreas Braxmeier | F6: =COUNTIF('Übersicht'!H$5:H$500, "Andreas Braxmeier") + COUNTIF('Übersicht'!I$5:I$500, "Andreas Braxmeier") -> 1 | H6: Villingen-Schwenningen | I6: =COUNTIF('Übersicht'!C$5:C$500, "Villingen-Schwenningen") -> 14 | K6: Kinder- & Jugendarbeit | L6: =COUNTIF('Übersicht'!B$5:B$500, "Kinder- & Jugendarbeit") -> 10
B7: Nachfragen | C7: =COUNTIF('Übersicht'!F$5:F$500, "Nachfragen") -> 0 | E7: Nadine Beha | F7: 2 | H7: St. Georgen | I7: =COUNTIF('Übersicht'!C$5:C$500, "St. Georgen") -> 6 | K7: Sportangebot | L7: =COUNTIF('Übersicht'!B$5:B$500, "Sportangebot") -> 10
B8: Zusage | C8: 3 | E8: Sophie Scheffler | F8: =COUNTIF('Übersicht'!H$5:H$500, "Sophie Scheffler") + COUNTIF('Übersicht'!I$5:I$500, "Sophie Scheffler") -> 4 | H8: Donaueschingen | I8: =COUNTIF('Übersicht'!C$5:C$500, "Donaueschingen") -> 4 | K8: Prävention | L8: =COUNTIF('Übersicht'!B$5:B$500, "Prävention") -> 6
B9: Terminiert | C9: 1 | E9: Ragavi Anusujantha | F9: 1 | H9: Bad Dürrheim | I9: =COUNTIF('Übersicht'!C$5:C$500, "Bad Dürrheim") -> 3 | K9: Soziales | L9: =COUNTIF('Übersicht'!B$5:B$500, "Soziales") -> 5
B10: Durchgeführt | C10: =COUNTIF('Übersicht'!F$5:F$500, "Durchgeführt") -> 4 | E10: Nina Ludwig | F10: =COUNTIF('Übersicht'!H$5:H$500, "Nina Ludwig") + COUNTIF('Übersicht'!I$5:I$500, "Nina Ludwig") -> 3 | H10: Triberg | I10: =COUNTIF('Übersicht'!C$5:C$500, "Triberg") -> 3 | K10: Beratung | L10: =COUNTIF('Übersicht'!B$5:B$500, "Beratung") -> 6
B11: Abgeschlossen | C11: =COUNTIF('Übersicht'!F$5:F$500, "Abgeschlossen") -> 0 | H11: Hüfingen | I11: =COUNTIF('Übersicht'!C$5:C$500, "Hüfingen") -> 3 | K11: BOS | L11: =COUNTIF('Übersicht'!B$5:B$500, "BOS") -> 4
B12: Absage | C12: =COUNTIF('Übersicht'!F$5:F$500, "Absage") -> 1 | H12: Schonach | I12: =COUNTIF('Übersicht'!C$5:C$500, "Schonach") -> 2 | K12: Musik | L12: =COUNTIF('Übersicht'!B$5:B$500, "Musik") -> 3
B18: Überblick Interviewpartner*innen
B19: Bezeichnung in Transkript | C19: Name | D19: Institution | E19: Interviewender 1+2
B20: B1 | C20: Frau Engesser | D20: Familenpass Bräunlingen | E20: Nadine + Ragavi
B21: B2 | C21: Herr Mengensdorf | D21: TV St. Georgen | E21: Nadine + Sophie
B22: B3 | C22: Frau Knöbel | D22: Pro Familia VS | E22: Nina + Andreas
B23: B4 | C23: Frau Rau | D23: Kreisjugendamt VS | E23: Sophie + Nadine
B24: B5 | C24: Herr Mielenz | D24: BEKJ Villingen-Schwenningen | E24: Sophie + Nina
B25: B6 | C25: Frau Slee | D25: Schulsozialarbeit GMS Eschach-Neckar | E25: Sophie + Nina
B26: B7
B27: B8
B28: B9
B29: B10
B30: B11
B31: B12

Sheet Nachrücker
A1: 1: Große Reichweite & Regelmäßiger Kontakt
A2: Akteur | B2: Angebotstyp | C2: Ort | D2: Ansprechpartner | E2: E-Mail | F2: Telefon | G2: Website (URL) | H2: Bereits Kontaktiert | I2: Kontaktdaten geprüft
A3: TV 1863 St. Georgen | B3: Sport | C3: St. Georgen | D3: Christine Hackenjos (Geschäftsführung) | E3: vorstand@tv-st-georgen.de | F3: ​07724 918481 | G3: info@tv-st-georgen.de | L3: Bedeutet, dass der Akteur bereits angeschrieben wurde Ggf gibt es mehrere Dopplungen der Akteuere beim Anschreiben bitte darauf achten
A4: Schwenninger ERC 04 | B4: Sport | C4: Schwenningen | D4: Geschäftsstelle | E4: info@wildwings-future.de | F4: 0049 – (0)7720 – 65429 | G4: wildwings.de | L4: Bedeutet, dass ich hier ein begründetes interesse habe tiefer einzugehen und die Akteure ggf. zu bevorzugen
A5: Ago e.V. | B5: Prävention | C5: Donaueschingen | D5: Dr. Thomas Meiworm | E5: info@ago-ev.de | F5: +49 771 8978181 | G5: verein-ago.de
A6: Georg Müller Schule | B6: Bildung | C6: Schwenningen | D6: Sekretariat | E6: info@gmsvs.de | F6: 07720-994747 | G6: gmsvs.de
A7: Neckarschule | B7: Bildung | C7: Schwenningen | D7: Schulleitung | E7: neckarschule@villingen-schwenningen.de | F7: +49 7720 821360 | G7: neckarschule.de
A8: SV 1921 Mühlhausen | B8: Kinderturnen | C8: Mühlhausen | D8: Allgemeine Mail wahrscheinlich aber Vorstand: Andreas Kohler & Daniel Wannack | E8: mail@sv1921muehlhausen.de | F8: +49 7720 989652 | G8: sv-muehlhausen.de
A9: Malteser Hilfsdienst | B9: Jugendgruppe (BOS) | C9: VS-Villingen | D9: Benjamin Crain | E9: benjamin.crain@malteser.org | F9: +49 7721 91700 | G9: malteser.de
A10: Ski-Club Villingen | B10: Sport (MTB) | C10: Villingen | D10: Jochen Menath (Vorstand) | E10: jochen.menath@skiclub-villingen.de | F10: +49 179 9062809 | G10: skiclub-villingen.de
A11: Psychol. Beratungsstelle (Ev./Kath.) | B11: Beratung | C11: VS-Schwenningen | D11: Zentrale Anmeldung | E11: info@tut.psychberatungsstelle.de | F11: +49 7720 7690 | G11: psychberatungsstelle.de
A12: TuS 1869 Bräunlingen | B12: Sport | C12: Bräunlingen | D12: Nicole Bobak (Geschäftsstelle)(Stand 2020 ggf neeuer) | E12: info@tusbraeunlingen.de | F12: +49 771 64080 | G12: tus-braeunlingen.de
A13: FC Viktoria Peterzell e.V. | B13: Sport | C13: St. Georgen | D13: Geschäftsstelle | E13: info@fcpeterzell.de | F13: +49 7724 1355 | G13: fcpeterzell.de
A14: FC Pfohren e.V. | B14: Sport | C14: Donaueschingen | D14: Geschäftsstelle | E14: info@fcpfohren.de | F14: +49 771 12399 | G14: fcpfohren.de
A15: Grundschule Kappel | B15: Bildung | C15: Niedereschach | D15: Carina Häsler (Extern von der Stadt, aber leitet die Vermittlung anscheinend für die Kindergärten) | E15: vormerkung.kita@niedereschach.de | F15: 49 7728 1363 (vom Kindergarten) von Carina: (0 77 28) 648-31 | G15: niedereschach.de
A16: Heinrich-Feurstein-Schule | B16: Bildung | C16: Donaueschingen | D16: Schulleitung | E16: info@hfs-ds.de | F16: +49 771 13139 | G16: hfs-ds.de
... A22: Dom Clemente Schule | B22: Bildung | C22: Schonach | D22: D. Tritschler | E22: d.tritschler@schonach.de | F22: +49 7722 9648121 | G22: dom-clemente-schule.de
A23: KHS (Wirtschaftsgymnasium) | B23: Bildung | C23: Donaueschingen | D23: Sekretariat | E23: info@khs-donaueschingen.de | F23: +49 771 83221-0 | G23: khs-donaueschingen.de | J23: Mail fehler
A24: Zirkus Confetti (TV Villingen) | B24: Kultur/Sport | C24: Villingen | D24: Larissa Eiternik | E24: info@zirkus-confetti.eu | F24: 07721 26408 (Nummer läuft über TV Villingen) | G24: zirkus-confetti.eu
A25: Anne-Frank-Grundschule | B25: Bildung | C25: Furtwangen | D25: Schulleitung | E25: schulleitung@afs-furtwangen.de | F25: 07723/6568200 | G25: https://www.afs-furtwangen.de/
A26: Bregtalschule (SBBZ) | B26: Bildung | C26: Furtwangen | D26: Markus Hummel | E26: info@bregtalschule.de | F26: +49 7723 912253 | G26: bregtalschule.de | J26: Mail fehler | P26: ins ca. 18 neue kontaktiert aus kategorie 1 und 2
A27: Kinderschutzbund VS | B27: Beratung | C27: Schwenningen | D27: Geschäftsstelle | E27: dksb@dksb-vs.de | F27: +49 7720 955930 | G27: dksb-vs.de
A28: DLRG Donaueschingen | B28: BOS | C28: Donaueschingen | D28: Thomas Moch | E28: info(at)baar.dlrg.de | F28: 07705 256480 | G28: donaueschingen.dlrg.de
A29: Jugendmusikschule | B29: Musik | C29: St. Georgen | D29: Verwaltung | E29: jms@jugendmusikschulen.de | F29: 07724/4968 | G29: st-georgen.de
A30: KiTa Schwalben-Nest | B30: KiTa | C30: Weiler | D30: Stefanie Höfgen | E30: Kita.schwalbennest.weiler@kbz.ekiba.de​ | F30: (0 77 25) 36 20 | G30: kita-schwalbennest.org
A31: Golden-Bühl-Schule | B31: Bildung | C31: Villingen | D31: Verwaltung | E31: goldenbuehlschule@villingen-schwenningen.de | F31: 07721 / 82-1621 | G31: goldenbuehlschule.de
A32: Thomas Strittmatter Gymnasium | B32: Bildung | C32: St. Georgen | E32: sekretariat@tsg-stgeorgen.de | G32: https://tsg-stgeorgen.de
A33: 2: Große Reichweite & Gelegentlicher Kontakt
A34: Akteur | B34: Angebotstyp | C34: Ort | D34: Ansprechpartner | E34: E-Mail | F34: Telefon | G34: Website (URL) | H34: Bereits Kontaktiert | I34: Kontaktdaten geprüft
A35: Sommerrainschule (Sportkooperation) | B35: Sport/Bildung | C35: St. Georgen | D35: Verwaltung | E35: sbbz-st.georgen@t-online.de | F35: 07724-87163 | G35: sommerrainschule.de
A36: GMS Eschach-Neckar (Schulhunde) | B36: Tiere/Bildung | C36: Niedereschach | D36: Fr. Rektorin Silke Wiest | E36: sekretariat@gms-eschach-neckar.de | F36: +49 7728 644910 | G36: gms-eschach-neckar.de
A37: Naturfreibad Schönwald | B37: Sportstätte | C37: Schönwald | D37: Tourist-Information | E37: info@schoenwald.de | F37: +49 7722 86080 | G37: schoenwald.de
A38: Dom Clemente (Bewegte Schule) | B38: Sport/Bildung | C38: Schonach | D38: Hr. Rektor Ralf Hellstab | E38: info@dom-clemente-schule.de | F38: +49 7722 9648121 | G38: dom-clemente-schule.de
A39: Polizei Triberg (Prävention) | B39: Prävention | C39: Triberg | D39: Referat Prävention VS | E39: konstanz.pp.praevention.vs@polizei.bwl.de | F39: +49 7722 916070 | G39: https://www.polizei-bw.de/
A40: Naturfreunde Bräunlingen | B40: Umwelt/Sport | C40: Bräunlingen | D40: Vorstand | E40: naturfreunde-braeunlingen@gmx.de | F40: (030) 29 77 32-60 (Nummer ggf. zur Hauptzentrale und nicht in die Ortsgruppe Bräunlingen) | G40: naturfreunde-braeunlingen.de
A41: MACH MIT! Museum | B41: Kultur | C41: Donaueschingen | D41: Verwaltung / Leitung (Konrad Hall) | E41: info@kijumu-donaueschingen.de | F41: 0771 92 94 74 26 | G41: Mach Mit
A42: Offene Hilfen (Lebenshilfe) | B42: Soziales | C42: Donaueschingen | D42: Hr. Mario Kienast | E42: info@lebenshilfe-vs.de | F42: +49 771 832620 | G42: Bruderhausdiakonie
A43: Gemeinde Niedereschach (Ferien) | B43: Betreuung | C43: Niedereschach | D43: Gemeinde Verwaltung (Ferienprogramm finde ich nicht aber vermutlich läuft es über die Verwaltung und die Schulen sind in Kooperation dabei... vielleicht stellen diese ja einen Kontakt her) | E43: info@niedereschach.de | F43: 07728 648-0 | G43: niedereschach.de
A44: DRK Ortsverein Triberg | B44: BOS | C44: Triberg | D44: Verwaltung | E44: info@drk-triberg.de | F44: (07722) 916430 | G44: drk-triberg.de
A45: Deutsche Kinderkrebsnachsorge | B45: Soziales | C45: Tannheim | D45: Verwaltung | E45: info@tannheim.de | F45: 07705 / 92 00 | G45: tannheim.de
...

Sheet Übersicht
A1: ÜBERSICHT | B1: Anzahl: 54
A4: Name | B4: Angebotstyp | C4: Stadt | D4: E-Mail | E4: Kategorie | F4: Status | G4: Ansprechpartner | H4: Interviewer 1 | I4: Interviewer 2 | J4: Datum | K4: Uhrzeit | L4: Dauer | M4: Art | N4: Ort / Link | O4: Themen | P4: Unterlagen
A5: Katholisches Familienzentrum St. Konrad | B5: Soziales / Selbsthilfe | C5: Villingen-Schwenningen | D5: kontakt@familienzentrum-stkonrad.de | E5: Groß & Regelmäßig | F5: Kontaktiert
A6: Ago e.V. | B6: Prävention | C6: Donaueschingen | D6: info@verein-ago.de | E6: Groß & Regelmäßig | F6: Kontaktiert
A7: Psychologische Beratungsstelle Ev./Kath. Kirche | B7: Beratung | C7: Villingen-Schwenningen | D7: gemeindebuero.schwenningen@elk-wue.de | E7: Groß & Regelmäßig | F7: Kontaktiert
A8: Sommerrainschule St. Georgen -- Sportangebote | B8: Sportangebot | C8: St. Georgen | D8: sbbz-st.georgen@t-online.de | E8: Groß & Regelmäßig | F8: Kontaktiert
A9: Kinderfeuerwehr St. Georgen | B9: BOS | C9: St. Georgen | D9: info@feuerwehr-st-georgen.de | E9: Groß & Regelmäßig | F9: Kontaktiert
A10: Neckarschule -- Klasse 2000 | B10: Prävention | C10: Villingen-Schwenningen | D10: neckarschule@villingen-schwenningen.de | E10: Groß & Regelmäßig | F10: Kontaktiert
A11: Georg Müller Grund- und Realschule -- Präventionskonzept | B11: Prävention | C11: Villingen-Schwenningen | D11: info@gmsvs.de | E11: Groß & Regelmäßig | F11: Kontaktiert
A12: Caritas Schwangerschaftsberatung | B12: Beratung | C12: Villingen-Schwenningen | D12: info@caritas-sbk.de | E12: Groß & Regelmäßig | F12: Kontaktiert
A13: Sozialpsychiatrischer Dienst (Caritas) | B13: Soziales | C13: Villingen-Schwenningen | D13: elke.schwarz@caritas-sbk.de | E13: Groß & Regelmäßig | F13: Kontaktiert
A14: Malteser Hilfsdienst -- Psychosoziale Notfallvorsorge | B14: BOS | C14: Villingen-Schwenningen | D14: Rainer.Kuehl@malteser.org | E14: Groß & Regelmäßig | F14: Kontaktiert
A15: AWO Haus der Kinder | B15: Betreuung | C15: Villingen-Schwenningen | D15: hausderkinder@awo-ov-vs.de | E15: Groß & Regelmäßig | F15: Kontaktiert
A16: Pro Familia Villingen-Schwenningen | B16: Beratung | C16: Villingen-Schwenningen | D16: vs-villingen@profamilia.de | E16: Groß & Regelmäßig | F16: Durchgeführt | G16: Frau Knöbel | H16: Nina Ludwig | I16: Andreas Braxmeier | J16: 46056 | K16: 0.41666667 | M16: Zoom
A17: Sportangebot Öfingen 1969 | B17: Sportangebot | C17: Bad Dürrheim | D17: jugend@sv-oefingen.de | E17: Groß & Regelmäßig | F17: Kontaktiert
A18: BEKJ Villingen-Schwenningen | B18: Beratung | C18: Villingen-Schwenningen | D18: beratungsstelle-bekj-fw@Lrasbk.de | E18: Groß & Gelegentlich | F18: Terminiert | G18: Herr Mielenz | H18: Sophie Scheffler | I18: Nina Ludwig | J18: 46057 | K18: 0.66666667 | M18: Zoom
A19: Polizei Triberg -- Präventionsvorträge | B19: Prävention | C19: Triberg | D19: Keine E-Mail! | E19: Groß & Gelegentlich | F19: Kontaktiert
A20: Schwarzwald-Gymnasium | B20: Beratung | C20: Triberg | D20: rf@schwarzwald-gymnasium.de | E20: Groß & Gelegentlich | F20: Kontaktiert
A21: Lernort Natur -- Jägervereinigung SBK | B21: Natur | C21: SBK | D21: kjm-kjv-sbk@outlook.de | E21: Groß & Gelegentlich | F21: Kontaktiert
A22: Naturfreunde | B22: Umweltschutz | C22: Bräunlingen | D22: naturfreunde-braeunlingen@gmx.de | E22: Groß & Gelegentlich | F22: Kontaktiert
A23: Kontaktstelle Beratung & Freizeit | B23: Soziales | C23: Donaueschingen | D23: David.Mueller@Bruderhausdiakonie.de | E23: Groß & Gelegentlich | F23: Kontaktiert
A24: Schulnetzwerk | B24: Bildung | C24: St. Georgen | D24: sekretariat@rsstg.de | E24: Groß & Gelegentlich | F24: Kontaktiert
A25: AWO Kinder- und Jugendhilfe | B25: Soziales | C25: Villingen-Schwenningen | D25: s.brunner@awo-ov-vs.de | E25: Groß & Gelegentlich | F25: Kontaktiert
A26: DRK -- Psychosoziale Notfallvorsorge | B26: BOS | C26: Villingen-Schwenningen | D26: mail@psnv-sbk.de | E26: Groß & Gelegentlich | F26: Kontaktiert
A27: Projekt Bewegte Schule -- Dom-Clemente-Schule | B27: Sportangebot | C27: Schonach | D27: d.tritschler@schonach.de | E27: Groß & Gelegentlich | F27: Kontaktiert
A28: Schönwälder Naturfreibad | B28: Sportstätte | C28: Schönwald | D28: mail@schoenwald.de | E28: Groß & Gelegentlich | F28: Ausgeschlossen
A29: Freibad Tannheim | B29: Sportstätte | C29: Tannheim | D29: info@freibad-tannheim.de | E29: Groß & Gelegentlich | F29: Ausgeschlossen
A30: Deutscher Kinderschutzbund OV | B30: Soziales | C30: Furtwangen | D30: info@dksb-furtwangen.de | E30: Groß & Gelegentlich | F30: Kontaktiert
... A53: Feuerwehr Schonach | B53: BOS | C53: Schonach | D53: ts@feuerwehr-schonach.de | E53: Klein & Gelegentlich | F53: Kontaktiert
A54: Städtischer Familienpass | B54: Kinder- & Jugendarbeit | C54: Bräunlingen | D54: Stephanie.engesser@braeunlingen.de | E54: Klein & Gelegentlich | F54: Durchgeführt | G54: Frau Engesser | H54: Nadine Beha | I54: Ragavi Anusujanthan | J54: 46049 | K54: 0.54166667 | M54: Präsenz | N54: Kirchstraße 10, 78199 Bräunlingen
A55: SBBZ Weiherdammschule | B55: Bildung / Beratung | C55: Blumberg | D55: info@weiherdammschule-blumberg.de | E55: Klein & Gelegentlich | F55: Zusage | G55: Herr Link?
A56: Schulsozialarbeit GMS Eschach-Neckar | B56: Kinder- & Jugendarbeit | C56: Niedereschach | D56: c_slee@lfa.org | E56: Klein & Gelegentlich | F56: Terminiert | G56: Frau Slee | H56: Sophie Scheffler | I56: Nina Ludwig | J56: 46063 | K56: 0.375 | M56: Zoom
A57: Sportkegelclub Rot-Weiß Unterkirnach | B57: Sportangebot | C57: Unterkirnach | D57: michaelstorzukn@t-online.de | E57: Klein & Gelegentlich | F57: Ausgeschlossen
A58: Trachtenkapelle Buchenberg | B58: Musik | C58: Königsfeld | D58: tk-buchenberg@t-online.de | E58: Klein & Gelegentlich | F58: Kontaktiert
A59: Turnverein St. Georgen | B59: Sportangebot | C59: St. Georgen | E59: Groß & Regelmäßig | F59: Durchgeführt | G59: Herr Mengesdorf | H59: Nadine Beha | I59: Sophie Scheffler | J59: 46050 | K59: 0.58333333 | M59: Präsenz | N59: Mühlstraße 2, 78112 St. Georgen
A60: Kreisjugendamt Villingen-Schwenningen | B60: Beratung | C60: Villingen-Schwenningen | D60: H.Rau@lrasbk.de | E60: Groß & Gelegentlich | F60: Durchgeführt | G60: Frau Rau | H60: Sophie Scheffler | I60: Nadine Beha | J60: 46056 | K60: 0.41666667 | M60: Zoom

Sheet Groß & Regelmäßig
A1: GROSS & REGELMÄSSIG | B1: Anzahl: 13
A4: Name | B4: Angebotstyp | C4: Stadt | D4: E-Mail | E4: Kategorie | F4: Status | G4: Ansprechpartner | H4: Interviewer 1 | I4: Interviewer 2 | J4: Datum | K4: Uhrzeit | L4: Dauer | M4: Art | N4: Ort / Link | O4: Themen | P4: Unterlagen
A5: Katholisches Familienzentrum St. Konrad | B5: Soziales / Selbsthilfe | C5: Villingen-Schwenningen | D5: kontakt@familienzentrum-stkonrad.de | E5: Groß & Regelmäßig
A6: Ago e.V. | B6: Prävention | C6: Donaueschingen | D6: info@verein-ago.de | E6: Groß & Regelmäßig
A7: Psychologische Beratungsstelle Ev./Kath. Kirche | B7: Beratung | C7: Villingen-Schwenningen | D7: gemeindebuero.schwenningen@elk-wue.de | E7: Groß & Regelmäßig
A8: Sommerrainschule St. Georgen -- Sportangebote | B8: Sportangebot | C8: St. Georgen | D8: sbbz-st.georgen@t-online.de | E8: Groß & Regelmäßig
A9: Kinderfeuerwehr St. Georgen | B9: BOS | C9: St. Georgen | D9: info@feuerwehr-st-georgen.de | E9: Groß & Regelmäßig
A10: Neckarschule -- Klasse 2000 | B10: Prävention | C10: Villingen-Schwenningen | D10: neckarschule@villingen-schwenningen.de | E10: Groß & Regelmäßig
A11: Georg Müller Grund- und Realschule -- Präventionskonzept | B11: Prävention | C11: Villingen-Schwenningen | D11: info@gmsvs.de | E11: Groß & Regelmäßig
A12: Caritas Schwangerschaftsberatung | B12: Beratung | C12: Villingen-Schwenningen | D12: info@caritas-sbk.de | E12: Groß & Regelmäßig
A13: Sozialpsychiatrischer Dienst (Caritas) | B13: Soziales | C13: Villingen-Schwenningen | D13: elke.schwarz@caritas-sbk.de | E13: Groß & Regelmäßig
A14: Malteser Hilfsdienst -- Psychosoziale Notfallvorsorge | B14: BOS | C14: Villingen-Schwenningen | D14: Rainer.Kuehl@malteser.org | E14: Groß & Regelmäßig
A15: AWO Haus der Kinder | B15: Betreuung | C15: Villingen-Schwenningen | D15: hausderkinder@awo-ov-vs.de | E15: Groß & Regelmäßig
A16: Pro Familia Villingen-Schwenningen | B16: Beratung | C16: Villingen-Schwenningen | D16: vs-villingen@profamilia.de | E16: Groß & Regelmäßig
A17: Sportangebot Öfingen 1969 | B17: Sportangebot | C17: Bad Dürrheim | D17: jugend@sv-oefingen.de | E17: Groß & Regelmäßig

Sheet Groß & Gelegentlich
A1: GROSS & GELEGENTLICH | B1: Anzahl: 14
A4: Name | B4: Angebotstyp | C4: Stadt | D4: E-Mail | E4: Kategorie | F4: Status | G4: Ansprechpartner | H4: Interviewer 1 | I4: Interviewer 2 | J4: Datum | K4: Uhrzeit | L4: Dauer | M4: Art | N4: Ort / Link | O4: Themen | P4: Unterlagen
A5: BEKJ Villingen-Schwenningen | B5: Beratung | C5: Villingen-Schwenningen | D5: beratungsstelle-bekj-fw@Lrasbk.de | E5: Groß & Gelegentlich
A6: Polizei Triberg -- Präventionsvorträge | B6: Prävention | C6: Triberg | D6: Keine E-Mail! | E6: Groß & Gelegentlich
A7: Schwarzwald-Gymnasium | B7: Beratung | C7: Triberg | D7: rf@schwarzwald-gymnasium.de | E7: Groß & Gelegentlich
A8: Lernort Natur -- Jägervereinigung SBK | B8: Natur | C8: SBK | D8: kjm-kjv-sbk@outlook.de | E8: Groß & Gelegentlich
A9: Naturfreunde | B9: Umweltschutz | C9: Bräunlingen | D9: naturfreunde-braeunlingen@gmx.de | E9: Groß & Gelegentlich
A10: Kontaktstelle Beratung & Freizeit | B10: Soziales | C10: Donaueschingen | D10: David.Mueller@Bruderhausdiakonie.de | E10: Groß & Gelegentlich
A11: Schulnetzwerk | B11: Bildung | C11: St. Georgen | D11: sekretariat@rsstg.de | E11: Groß & Gelegentlich
A12: AWO Kinder- und Jugendhilfe | B12: Soziales | C12: Villingen-Schwenningen | D12: s.brunner@awo-ov-vs.de | E12: Groß & Gelegentlich
A13: DRK -- Psychosoziale Notfallvorsorge | B13: BOS | C13: Villingen-Schwenningen | D13: mail@psnv-sbk.de | E13: Groß & Gelegentlich
A14: Projekt Bewegte Schule -- Dom-Clemente-Schule | B14: Sportangebot | C14: Schonach | D14: d.tritschler@schonach.de | E14: Groß & Gelegentlich
A15: Schönwälder Naturfreibad | B15: Sportstätte | C15: Schönwald | D15: mail@schoenwald.de | E15: Groß & Gelegentlich
A16: Freibad Tannheim | B16: Sportstätte | C16: Tannheim | D16: info@freibad-tannheim.de | E16: Groß & Gelegentlich
... A18: BUND Ortsverband | B18: Umweltschutz | C18: Königsfeld | D18: bund.sbh@bund.net | E18: Groß & Gelegentlich

Sheet Klein & Regelmäßig
A1: KLEIN & REGELMÄSSIG | B1: Anzahl: 14
A4: Name | B4: Angebotstyp | C4: Stadt | D4: E-Mail | E4: Kategorie | F4: Status | G4: Ansprechpartner | H4: Interviewer 1 | I4: Interviewer 2 | J4: Datum | K4: Uhrzeit | L4: Dauer | M4: Art | N4: Ort / Link | O4: Themen | P4: Unterlagen
A5: Bundesverband Psychiatrie-Erfahrener e.V. | B5: Selbsthilfe | C5: Villingen-Schwenningen | D5: kontakt-info@bpe-online.de | E5: Klein & Regelmäßig
A6: Jugendhaus Fürstenberg | B6: Kinder- & Jugendarbeit | C6: Hüfingen | D6: Svenja.markowitsch@huefingen.de | E6: Klein & Regelmäßig
A7: Jugendtreff Hasen | B7: Kinder- & Jugendarbeit | C7: Tuningen | D7: Jugendtreff-hasen@web.de | E7: Klein & Regelmäßig
A8: Jugendclub Schabenhausen | B8: Kinder- & Jugendarbeit | C8: Niedereschach | D8: info@jc-niederschach.de | E8: Klein & Regelmäßig
A9: Naturparkschule Josef-Hebting-Schule | B9: Natur | C9: Vöhrenbach | D9: sekretariat@jhs-voehrenbach.de | E9: Klein & Regelmäßig
A10: Jugendhaus Blumberg | B10: Kinder- & Jugendarbeit | C10: Blumberg | D10: sasa.hustic@stadt-blumberg.de | E10: Klein & Regelmäßig
A11: Jugendhaus Behla | B11: Kinder- & Jugendarbeit | C11: Hüfingen | D11: Svenja.markowitsch@huefingen.de | E11: Klein & Regelmäßig
A12: Generationentreff LEBENSWert | B12: Soziales | C12: Bad Dürrheim | D12: info@generationentreff-lebenswert.de | E12: Klein & Regelmäßig
A13: Jugendmusikschule -- Musikalische Früherziehung | B13: Musik | C13: Triberg | D13: jms@jugendmusikschulen.de | E13: Klein & Regelmäßig
A14: Jugendtreff | B14: Kinder- & Jugendarbeit | C14: Furtwangen | D14: Dmaute.stadt@furtwangen.de | E14: Klein & Regelmäßig
A15: Reitsportgemeinschaft Gnadental | B15: Sportangebot | C15: Donaueschingen | D15: (Tel. 0771 61723) | E15: Klein & Regelmäßig
A16: Reit- und Fahrverein Donaueschingen e.V. | B16: Sportangebot | C16: Donaueschingen | D16: vorstand1@ruf-donaueschingen.de | E16: Klein & Regelmäßig
... A18: Jugendhaus Hüfingen | B18: Kinder- & Jugendarbeit | C18: Hüfingen | D18: Svenja.markowitsch@huefingen.de | E18: Klein & Regelmäßig

Sheet Klein & Gelegentlich
A1: KLEIN & GELEGENTLICH | B1: Anzahl: 13
A4: Name | B4: Angebotstyp | C4: Stadt | D4: E-Mail | E4: Kategorie | F4: Status | G4: Ansprechpartner | H4: Interviewer 1 | I4: Interviewer 2 | J4: Datum | K4: Uhrzeit | L4: Dauer | M4: Art | N4: Ort / Link | O4: Themen | P4: Unterlagen
A5: Initiative Gesund leben in St. Georgen | B5: Prävention | C5: St. Georgen | D5: (Keine Mail gefunden) | E5: Klein & Gelegentlich
A6: Blaues Kreuz in Deutschland e.V. | B6: Prävention | C6: St. Georgen | D6: b.becker@bluprevent.de | E6: Klein & Gelegentlich
A7: Kegel Sport Club Brigachtal | B7: Sportangebot | C7: Brigachtal | D7: Gunnar.tr@web.de | E7: Klein & Gelegentlich
A8: Fischereigemeinschaft Gütenbach | B8: Sportangebot | C8: Gütenbach | D8: info@guetenbach.de | E8: Klein & Gelegentlich
A9: Sportkegelclub Kegelfreunde Unterkirnach | B9: Sportangebot | C9: Unterkirnach | D9: vorstand.skckegelfreundeunterkirnach@gmx.de | E9: Klein & Gelegentlich
A10: Harmonikaverein & Josef-Hebting-Schule | B10: Musik | C10: Vöhrenbach | D10: marinaguenter@gmx.de | E10: Klein & Gelegentlich
A11: VHS Tuningen | B11: Bildung | C11: Tuningen | D11: vhs@villingen-schwenningen.de | E11: Klein & Gelegentlich
A12: Feuerwehr Schonach | B12: BOS | C12: Schonach | D12: ts@feuerwehr-schonach.de | E12: Klein & Gelegentlich
A13: Städtischer Familienpass | B13: Kinder- & Jugendarbeit | C13: Bräunlingen | D13: Stephanie.engesser@braeunlingen.de | E13: Klein & Gelegentlich
A14: SBBZ Weiherdammschule | B14: Bildung / Beratung | C14: Blumberg | D14: info@weiherdammschule-blumberg.de | E14: Klein & Gelegentlich
A15: Schulsozialarbeit GMS Eschach-Neckar | B15: Kinder- & Jugendarbeit | C15: Niedereschach | D15: d_storz@lfa.org | E15: Klein & Gelegentlich
A16: Sportkegelclub Rot-Weiß Unterkirnach | B16: Sportangebot | C16: Unterkirnach | D16: michaelstorzukn@t-online.de | E16: Klein & Gelegentlich
A17: Trachtenkapelle Buchenberg | B17: Musik | C17: Königsfeld | D17: tk-buchenberg@t-online.de | E17: Klein & Gelegentlich
